2022-06-30 21:27:35,550 INFO    MainThread:25812 [internal.py:wandb_internal():93] W&B internal server running at pid: 25812, started at: 2022-06-30 21:27:35.549847
2022-06-30 21:27:35,552 INFO    WriterThread:25812 [datastore.py:open_for_write():75] open: C:\Users\DESKTOP\Desktop\github repo\KDD_TACCO\wandb\run-20220630_212734-vmv9fxng\run-vmv9fxng.wandb
2022-06-30 21:27:35,554 DEBUG   SenderThread:25812 [sender.py:send():235] send: header
2022-06-30 21:27:35,555 DEBUG   SenderThread:25812 [sender.py:send():235] send: run
2022-06-30 21:27:35,766 ERROR   SenderThread:25812 [internal_api.py:execute():143] 404 response executing GraphQL.
2022-06-30 21:27:35,767 ERROR   SenderThread:25812 [internal_api.py:execute():144] {"errors":[{"message":"entity khd08 not found during upsertBucket","path":["upsertBucket"]}],"data":{"upsertBucket":null}}
2022-06-30 21:27:36,558 INFO    WriterThread:25812 [datastore.py:close():279] close: C:\Users\DESKTOP\Desktop\github repo\KDD_TACCO\wandb\run-20220630_212734-vmv9fxng\run-vmv9fxng.wandb
2022-06-30 21:27:36,559 INFO    HandlerThread:25812 [handler.py:finish():806] shutting down handler
2022-06-30 21:27:36,560 ERROR   MainThread:25812 [internal.py:wandb_internal():165] Thread SenderThread:
Traceback (most recent call last):
  File "C:\Users\DESKTOP\anaconda3\envs\a2\lib\site-packages\wandb\sdk\lib\retry.py", line 108, in __call__
    result = self._call_fn(*args, **kwargs)
  File "C:\Users\DESKTOP\anaconda3\envs\a2\lib\site-packages\wandb\sdk\internal\internal_api.py", line 140, in execute
    return self.client.execute(*args, **kwargs)
  File "C:\Users\DESKTOP\anaconda3\envs\a2\lib\site-packages\wandb\vendor\gql-0.2.0\wandb_gql\client.py", line 52, in execute
    result = self._get_result(document, *args, **kwargs)
  File "C:\Users\DESKTOP\anaconda3\envs\a2\lib\site-packages\wandb\vendor\gql-0.2.0\wandb_gql\client.py", line 60, in _get_result
    return self.transport.execute(document, *args, **kwargs)
  File "C:\Users\DESKTOP\anaconda3\envs\a2\lib\site-packages\wandb\vendor\gql-0.2.0\wandb_gql\transport\requests.py", line 39, in execute
    request.raise_for_status()
  File "C:\Users\DESKTOP\anaconda3\envs\a2\lib\site-packages\requests\models.py", line 960, in raise_for_status
    raise HTTPError(http_error_msg, response=self)
requests.exceptions.HTTPError: 404 Client Error: Not Found for url: https://api.wandb.ai/graphql

During handling of the above exception, another exception occurred:

Traceback (most recent call last):
  File "C:\Users\DESKTOP\anaconda3\envs\a2\lib\site-packages\wandb\apis\normalize.py", line 22, in wrapper
    return func(*args, **kwargs)
  File "C:\Users\DESKTOP\anaconda3\envs\a2\lib\site-packages\wandb\sdk\internal\internal_api.py", line 1319, in upsert_run
    response = self.gql(mutation, variable_values=variable_values, **kwargs)
  File "C:\Users\DESKTOP\anaconda3\envs\a2\lib\site-packages\wandb\sdk\lib\retry.py", line 124, in __call__
    if not check_retry_fn(e):
  File "C:\Users\DESKTOP\anaconda3\envs\a2\lib\site-packages\wandb\util.py", line 887, in no_retry_auth
    raise CommError("Permission denied, ask the project owner to grant you access")
wandb.errors.CommError: Permission denied, ask the project owner to grant you access

During handling of the above exception, another exception occurred:

Traceback (most recent call last):
  File "C:\Users\DESKTOP\anaconda3\envs\a2\lib\site-packages\wandb\sdk\internal\internal_util.py", line 51, in run
    self._run()
  File "C:\Users\DESKTOP\anaconda3\envs\a2\lib\site-packages\wandb\sdk\internal\internal_util.py", line 102, in _run
    self._process(record)
  File "C:\Users\DESKTOP\anaconda3\envs\a2\lib\site-packages\wandb\sdk\internal\internal.py", line 310, in _process
    self._sm.send(record)
  File "C:\Users\DESKTOP\anaconda3\envs\a2\lib\site-packages\wandb\sdk\internal\sender.py", line 237, in send
    send_handler(record)
  File "C:\Users\DESKTOP\anaconda3\envs\a2\lib\site-packages\wandb\sdk\internal\sender.py", line 695, in send_run
    self._init_run(run, config_value_dict)
  File "C:\Users\DESKTOP\anaconda3\envs\a2\lib\site-packages\wandb\sdk\internal\sender.py", line 733, in _init_run
    commit=run.git.last_commit or None,
  File "C:\Users\DESKTOP\anaconda3\envs\a2\lib\site-packages\wandb\apis\normalize.py", line 58, in wrapper
    raise CommError(message, err).with_traceback(sys.exc_info()[2])
  File "C:\Users\DESKTOP\anaconda3\envs\a2\lib\site-packages\wandb\apis\normalize.py", line 22, in wrapper
    return func(*args, **kwargs)
  File "C:\Users\DESKTOP\anaconda3\envs\a2\lib\site-packages\wandb\sdk\internal\internal_api.py", line 1319, in upsert_run
    response = self.gql(mutation, variable_values=variable_values, **kwargs)
  File "C:\Users\DESKTOP\anaconda3\envs\a2\lib\site-packages\wandb\sdk\lib\retry.py", line 124, in __call__
    if not check_retry_fn(e):
  File "C:\Users\DESKTOP\anaconda3\envs\a2\lib\site-packages\wandb\util.py", line 887, in no_retry_auth
    raise CommError("Permission denied, ask the project owner to grant you access")
wandb.errors.CommError: Permission denied, ask the project owner to grant you access
2022-06-30 21:27:38,601 INFO    MainThread:25812 [internal.py:handle_exit():80] Internal process exited
