2022-06-30 21:19:13,898 INFO    MainThread:31392 [internal.py:wandb_internal():93] W&B internal server running at pid: 31392, started at: 2022-06-30 21:19:13.897756
2022-06-30 21:19:13,900 INFO    WriterThread:31392 [datastore.py:open_for_write():75] open: C:\Users\DESKTOP\Desktop\github repo\KDD_TACCO\wandb\run-20220630_211912-s24cypeu\run-s24cypeu.wandb
2022-06-30 21:19:13,902 DEBUG   SenderThread:31392 [sender.py:send():235] send: header
2022-06-30 21:19:13,902 DEBUG   SenderThread:31392 [sender.py:send():235] send: run
2022-06-30 21:19:14,098 ERROR   SenderThread:31392 [internal_api.py:execute():143] 403 response executing GraphQL.
2022-06-30 21:19:14,098 ERROR   SenderThread:31392 [internal_api.py:execute():144] {"errors":[{"message":"permission denied","path":["upsertBucket"],"extensions":{"code":"PERMISSION_ERROR"}}],"data":{"upsertBucket":null}}
2022-06-30 21:19:14,915 INFO    WriterThread:31392 [datastore.py:close():279] close: C:\Users\DESKTOP\Desktop\github repo\KDD_TACCO\wandb\run-20220630_211912-s24cypeu\run-s24cypeu.wandb
2022-06-30 21:19:14,915 INFO    HandlerThread:31392 [handler.py:finish():806] shutting down handler
2022-06-30 21:19:14,917 ERROR   MainThread:31392 [internal.py:wandb_internal():165] Thread SenderThread:
Traceback (most recent call last):
  File "C:\Users\DESKTOP\anaconda3\envs\a2\lib\site-packages\wandb\sdk\lib\retry.py", line 108, in __call__
    result = self._call_fn(*args, **kwargs)
  File "C:\Users\DESKTOP\anaconda3\envs\a2\lib\site-packages\wandb\sdk\internal\internal_api.py", line 140, in execute
    return self.client.execute(*args, **kwargs)
  File "C:\Users\DESKTOP\anaconda3\envs\a2\lib\site-packages\wandb\vendor\gql-0.2.0\wandb_gql\client.py", line 52, in execute
    result = self._get_result(document, *args, **kwargs)
  File "C:\Users\DESKTOP\anaconda3\envs\a2\lib\site-packages\wandb\vendor\gql-0.2.0\wandb_gql\client.py", line 60, in _get_result
    return self.transport.execute(document, *args, **kwargs)
  File "C:\Users\DESKTOP\anaconda3\envs\a2\lib\site-packages\wandb\vendor\gql-0.2.0\wandb_gql\transport\requests.py", line 39, in execute
    request.raise_for_status()
  File "C:\Users\DESKTOP\anaconda3\envs\a2\lib\site-packages\requests\models.py", line 960, in raise_for_status
    raise HTTPError(http_error_msg, response=self)
requests.exceptions.HTTPError: 403 Client Error: Forbidden for url: https://api.wandb.ai/graphql

During handling of the above exception, another exception occurred:

Traceback (most recent call last):
  File "C:\Users\DESKTOP\anaconda3\envs\a2\lib\site-packages\wandb\apis\normalize.py", line 22, in wrapper
    return func(*args, **kwargs)
  File "C:\Users\DESKTOP\anaconda3\envs\a2\lib\site-packages\wandb\sdk\internal\internal_api.py", line 1319, in upsert_run
    response = self.gql(mutation, variable_values=variable_values, **kwargs)
  File "C:\Users\DESKTOP\anaconda3\envs\a2\lib\site-packages\wandb\sdk\lib\retry.py", line 124, in __call__
    if not check_retry_fn(e):
  File "C:\Users\DESKTOP\anaconda3\envs\a2\lib\site-packages\wandb\util.py", line 887, in no_retry_auth
    raise CommError("Permission denied, ask the project owner to grant you access")
wandb.errors.CommError: Permission denied, ask the project owner to grant you access

During handling of the above exception, another exception occurred:

Traceback (most recent call last):
  File "C:\Users\DESKTOP\anaconda3\envs\a2\lib\site-packages\wandb\sdk\internal\internal_util.py", line 51, in run
    self._run()
  File "C:\Users\DESKTOP\anaconda3\envs\a2\lib\site-packages\wandb\sdk\internal\internal_util.py", line 102, in _run
    self._process(record)
  File "C:\Users\DESKTOP\anaconda3\envs\a2\lib\site-packages\wandb\sdk\internal\internal.py", line 310, in _process
    self._sm.send(record)
  File "C:\Users\DESKTOP\anaconda3\envs\a2\lib\site-packages\wandb\sdk\internal\sender.py", line 237, in send
    send_handler(record)
  File "C:\Users\DESKTOP\anaconda3\envs\a2\lib\site-packages\wandb\sdk\internal\sender.py", line 695, in send_run
    self._init_run(run, config_value_dict)
  File "C:\Users\DESKTOP\anaconda3\envs\a2\lib\site-packages\wandb\sdk\internal\sender.py", line 733, in _init_run
    commit=run.git.last_commit or None,
  File "C:\Users\DESKTOP\anaconda3\envs\a2\lib\site-packages\wandb\apis\normalize.py", line 58, in wrapper
    raise CommError(message, err).with_traceback(sys.exc_info()[2])
  File "C:\Users\DESKTOP\anaconda3\envs\a2\lib\site-packages\wandb\apis\normalize.py", line 22, in wrapper
    return func(*args, **kwargs)
  File "C:\Users\DESKTOP\anaconda3\envs\a2\lib\site-packages\wandb\sdk\internal\internal_api.py", line 1319, in upsert_run
    response = self.gql(mutation, variable_values=variable_values, **kwargs)
  File "C:\Users\DESKTOP\anaconda3\envs\a2\lib\site-packages\wandb\sdk\lib\retry.py", line 124, in __call__
    if not check_retry_fn(e):
  File "C:\Users\DESKTOP\anaconda3\envs\a2\lib\site-packages\wandb\util.py", line 887, in no_retry_auth
    raise CommError("Permission denied, ask the project owner to grant you access")
wandb.errors.CommError: Permission denied, ask the project owner to grant you access
2022-06-30 21:19:16,964 INFO    MainThread:31392 [internal.py:handle_exit():80] Internal process exited
